<?xml version='1.0' encoding='utf-8'?>
<robot xmlns:xacro="http://www.ros.org/wiki/xacro" name="mz25">
  <xacro:macro name="mz25_arm" params="arm_id:='mz25' description_pkg:='mz25_robot_description' connected_to:='' xyz:='0 0 0' rpy:='0 0 0'">
    <xacro:unless value="${not connected_to}">
      <joint name="${arm_id}_joint_${connected_to}" type="fixed">
        <parent link="${connected_to}"/>
        <child link="${arm_id}_link0"/>
        <origin rpy="${rpy}" xyz="${xyz}"/>
      </joint>
    </xacro:unless>

    <!-- for simulation -->
    <!--    <link name="world" />-->

    <!--    <joint name="robot_to_world" type="fixed">-->
    <!--      <parent link="world" />-->
    <!--      <child link="${arm_id}_link0" />-->
    <!--      <origin xyz="0.0 0.0 0.0" rpy="0.0 0.0 0.0" />-->
    <!--    </joint>-->

    <xacro:property name="joint_damping" value="1.0"/>
    <!-- end for simulation -->

    <link name="${arm_id}_link0">
      <visual>
        <geometry>
          <mesh filename="package://${description_pkg}/meshes/visual/link0.dae"/>
        </geometry>
      </visual>
      <collision>
        <geometry>
          <mesh filename="package://${description_pkg}/meshes/collision/link0.stl"/>
        </geometry>
      </collision>
    </link>
    <link name="${arm_id}_link1">
      <visual>
        <geometry>
          <mesh filename="package://${description_pkg}/meshes/visual/link1.dae"/>
        </geometry>
      </visual>
      <collision>
        <geometry>
          <mesh filename="package://${description_pkg}/meshes/collision/link1.stl"/>
        </geometry>
      </collision>

      <!-- for simulation -->
      <inertial>
        <origin xyz="0 0 0" rpy="0 0 0" />
        <mass value="2.34" />
        <inertia ixx="0.3" ixy="0.0" ixz="0.0" iyy="0.3" iyz="0.0" izz="0.3" />
      </inertial>
      <!-- end for simulation -->
    </link>
    <joint name="${arm_id}_joint1" type="revolute">
      <safety_controller k_position="100.0" k_velocity="40.0" soft_lower_limit="-2.97" soft_upper_limit="2.97"/>
      <origin rpy="0 0 0" xyz="0 0 0.2495"/>
      <parent link="${arm_id}_link0"/>
      <child link="${arm_id}_link1"/>
      <axis xyz="0 0 1"/>
      <limit effort="400" lower="-2.97" upper="2.97" velocity="3.67"/>

      <!-- for simulation -->
      <dynamics damping="${joint_damping}"/>
      <!-- end for simulation -->
    </joint>
    <link name="${arm_id}_link2">
      <visual>
        <geometry>
          <mesh filename="package://${description_pkg}/meshes/visual/link2.dae"/>
        </geometry>
      </visual>
      <collision>
        <geometry>
          <mesh filename="package://${description_pkg}/meshes/collision/link2.stl"/>
        </geometry>
      </collision>

      <!-- for simulation -->
      <inertial>
        <origin xyz="0 0 0" rpy="0 0 0" />
        <mass value="23.6" />
        <inertia ixx="0.3" ixy="0.0" ixz="0.0" iyy="0.3" iyz="0.0" izz="0.3" />
      </inertial>
      <!-- end for simulation -->
    </link>
    <joint name="${arm_id}_joint2" type="revolute">
      <safety_controller k_position="100.0" k_velocity="40.0" soft_lower_limit="-2.62" soft_upper_limit="1.83"/>
      <origin rpy="0 0 ${-pi/2}" xyz="0.17 0.157 0.3005"/>
      <parent link="${arm_id}_link1"/>
      <child link="${arm_id}_link2"/>
      <axis xyz="1 0 0"/>
      <limit effort="400" lower="-2.62" upper="1.83" velocity="3.23"/>

      <!-- for simulation -->
      <dynamics damping="${joint_damping}"/>
      <!-- end for simulation -->
    </joint>
    <link name="${arm_id}_link3">
      <visual>
        <geometry>
          <mesh filename="package://${description_pkg}/meshes/visual/link3.dae"/>
        </geometry>
      </visual>
      <collision>
        <geometry>
          <mesh filename="package://${description_pkg}/meshes/collision/link3.stl"/>
        </geometry>
      </collision>

      <!-- for simulation -->
      <inertial>
        <origin xyz="0 0 0" rpy="0 0 0" />
        <mass value="23.8" />
        <inertia ixx="0.3" ixy="0.0" ixz="0.0" iyy="0.3" iyz="0.0" izz="0.3" />
      </inertial>
      <!-- end for simulation -->
    </link>
    <joint name="${arm_id}_joint3" type="revolute">
      <safety_controller k_position="100.0" k_velocity="40.0" soft_lower_limit="-1.43" soft_upper_limit="3.21"/>
      <origin rpy="0 0 ${pi/2}" xyz="0.157 0 0.88"/>
      <parent link="${arm_id}_link2"/>
      <child link="${arm_id}_link3"/>
      <axis xyz="0 -1 0"/>
      <limit effort="400" lower="-1.43" upper="3.21" velocity="4.71"/>

      <!-- for simulation -->
      <dynamics damping="${joint_damping}"/>
      <!-- end for simulation -->
    </joint>
    <link name="${arm_id}_link4">
      <visual>
        <geometry>
          <mesh filename="package://${description_pkg}/meshes/visual/link4.dae"/>
        </geometry>
      </visual>
      <collision>
        <geometry>
          <mesh filename="package://${description_pkg}/meshes/collision/link4.stl"/>
        </geometry>
      </collision>

      <!-- for simulation -->
      <inertial>
        <origin xyz="0 0 0" rpy="0 0 0" />
        <mass value="24.3" />
        <inertia ixx="0.3" ixy="0.0" ixz="0.0" iyy="0.3" iyz="0.0" izz="0.3" />
      </inertial>
      <!-- end for simulation -->
    </link>
    <joint name="${arm_id}_joint4" type="revolute">
      <safety_controller k_position="100.0" k_velocity="40.0" soft_lower_limit="-3.32" soft_upper_limit="3.32"/>
      <origin rpy="0 0 0" xyz="0.81 0 0.19"/>
      <parent link="${arm_id}_link3"/>
      <child link="${arm_id}_link4"/>
      <axis xyz="1 0 0"/>
      <limit effort="400" lower="-3.32" upper="3.32" velocity="7.33"/>

      <!-- for simulation -->
      <dynamics damping="${joint_damping}"/>
      <!-- end for simulation -->
    </joint>
    <link name="${arm_id}_link5">
      <visual>
        <geometry>
          <mesh filename="package://${description_pkg}/meshes/visual/link5.dae"/>
        </geometry>
      </visual>
      <collision>
        <geometry>
          <mesh filename="package://${description_pkg}/meshes/collision/link5.stl"/>
        </geometry>
      </collision>

      <!-- for simulation -->
      <inertial>
        <origin xyz="0 0 0" rpy="0 0 0" />
        <mass value="35" />
        <inertia ixx="0.3" ixy="0.0" ixz="0.0" iyy="0.3" iyz="0.0" izz="0.3" />
      </inertial>
      <!-- end for simulation -->
    </link>
    <joint name="${arm_id}_joint5" type="revolute">
      <safety_controller k_position="100.0" k_velocity="40.0" soft_lower_limit="-2.53" soft_upper_limit="2.53"/>
      <origin rpy="0 0 0" xyz="0 0 0"/>
      <parent link="${arm_id}_link4"/>
      <child link="${arm_id}_link5"/>
      <axis xyz="0 -1 0"/>
      <limit effort="60" lower="-2.53" upper="2.53" velocity="7.33"/>

      <!-- for simulation -->
      <dynamics damping="${joint_damping}"/>
      <!-- end for simulation -->
    </joint>
    <link name="${arm_id}_link6">
      <visual>
        <geometry>
          <mesh filename="package://${description_pkg}/meshes/visual/link6.dae"/>
        </geometry>
      </visual>
      <collision>
        <geometry>
          <mesh filename="package://${description_pkg}/meshes/collision/link6.stl"/>
        </geometry>
      </collision>

      <!-- for simulation -->
      <inertial>
        <origin xyz="0 0 0" rpy="0 0 0" />
        <mass value="1.47" />
        <inertia ixx="0.3" ixy="0.0" ixz="0.0" iyy="0.3" iyz="0.0" izz="0.3" />
      </inertial>
      <!-- end for simulation -->
    </link>
    <joint name="${arm_id}_joint6" type="revolute">
      <safety_controller k_position="100.0" k_velocity="40.0" soft_lower_limit="-6.28" soft_upper_limit="6.28"/>
      <origin rpy="0 0 0" xyz="0.101 0 0"/>
      <parent link="${arm_id}_link5"/>
      <child link="${arm_id}_link6"/>
      <axis xyz="1 0 0"/>
      <limit effort="12" lower="-6.28" upper="6.28" velocity="11.73"/>

      <!-- for simulation -->
      <dynamics damping="${joint_damping}"/>
      <!-- end for simulation -->
    </joint>
  </xacro:macro>
</robot>
